######################################################################
## Python 2.6 error log
######################################################################

======================================================================
ERROR: test suite for <module 'tests.integration' from '/home/lucas/Programming/Python/cassandra/python-driver/tests/integration/__init__.pyc'>
----------------------------------------------------------------------
Traceback (most recent call last):
  File "/home/lucas/Programming/Python/cassandra/venv/2.6/lib/python2.6/site-packages/nose/suite.py", line 208, in run
    self.setUp()
  File "/home/lucas/Programming/Python/cassandra/venv/2.6/lib/python2.6/site-packages/nose/suite.py", line 291, in setUp
    self.setupContext(ancestor)
  File "/home/lucas/Programming/Python/cassandra/venv/2.6/lib/python2.6/site-packages/nose/suite.py", line 314, in setupContext
    try_run(context, names)
  File "/home/lucas/Programming/Python/cassandra/venv/2.6/lib/python2.6/site-packages/nose/util.py", line 469, in try_run
    return func()
  File "/home/lucas/Programming/Python/cassandra/python-driver/tests/integration/__init__.py", line 74, in setup_package
    cluster.start(wait_for_binary_proto=True)
  File "/home/lucas/Programming/Python/cassandra/venv/2.6/lib/python2.6/site-packages/ccmlib/cluster.py", line 208, in start
    p = node.start(update_pid=False)
  File "/home/lucas/Programming/Python/cassandra/venv/2.6/lib/python2.6/site-packages/ccmlib/node.py", line 304, in start
    common.check_socket_available(itf)
  File "/home/lucas/Programming/Python/cassandra/venv/2.6/lib/python2.6/site-packages/ccmlib/common.py", line 149, in check_socket_available
    raise UnavailableSocketError("Inet address %s:%s is not available: %s" % (addr, port, msg))
UnavailableSocketError: Inet address 127.0.0.1:7000 is not available: [Errno 98] Address already in use

======================================================================
ERROR: Smoke test cass_parameterized_type_with
----------------------------------------------------------------------
Traceback (most recent call last):
  File "/home/lucas/Programming/Python/cassandra/python-driver/tests/unit/test_types.py", line 81, in test_cassandratype
    self.assertEqual(LongType.cass_parameterized_type_with(()), 'LongType')
  File "/home/lucas/Programming/Python/cassandra/python-driver/cassandra/cqltypes.py", line 229, in cass_parameterized_type_with
    cname = cls.cassname
AttributeError: type object 'LongType' has no attribute 'cassname'

======================================================================
FAIL: test_partial_header_read (tests.unit.io.test_asyncorereactor.AsyncoreConnectionTest)
----------------------------------------------------------------------
Traceback (most recent call last):
  File "/home/lucas/Programming/Python/cassandra/python-driver/tests/unit/io/test_asyncorereactor.py", line 245, in test_partial_header_read
    self.assertFalse(c.is_defunct)
AssertionError: True is not False
-------------------- >> begin captured logging << --------------------
cassandra.connection: DEBUG: Sending initial options message for new connection (40990800) to 1.2.3.4
cassandra.io.asyncorereactor: DEBUG: Starting asyncore event loop
cassandra.io.asyncorereactor: DEBUG: Asyncore event loop stopped unexepectedly
Traceback (most recent call last):
  File "/home/lucas/Programming/Python/cassandra/python-driver/cassandra/io/asyncorereactor.py", line 45, in _run_loop
    asyncore.loop(timeout=0.001, use_poll=True, count=None)
  File "/usr/local/lib/python2.6/asyncore.py", line 210, in loop
    poll_fun(timeout, map)
  File "/usr/local/lib/python2.6/asyncore.py", line 184, in poll2
    pollster.register(fd, flags)
TypeError: fileno() returned a non-integer
cassandra.io.asyncorereactor: DEBUG: Asyncore event loop ended
cassandra.connection: ERROR: Error decoding response from Cassandra. opcode: 0006; message contents: '\x00\x02\x00\x0bCQL_VERSION\x00\x01\x00\x053.0.1\x00\x0bCOMPRESSION\x00\x00'
Traceback (most recent call last):
  File "/home/lucas/Programming/Python/cassandra/python-driver/cassandra/connection.py", line 199, in process_msg
    response = decode_response(stream_id, flags, opcode, body, self.decompressor)
  File "/home/lucas/Programming/Python/cassandra/python-driver/cassandra/decoder.py", line 155, in decode_response
    msg_class = _message_types_by_opcode[opcode]
KeyError: 6
cassandra.connection: ERROR: Did not get expected SupportedMessage response; instead, got: 6
cassandra.io.asyncorereactor: DEBUG: Defuncting connection (40990800) to 1.2.3.4: Did not get expected SupportedMessage response; instead, got: 6
Traceback (most recent call last):
  File "/home/lucas/Programming/Python/cassandra/python-driver/cassandra/connection.py", line 103, in wrapper
    return f(self, *args, **kwargs)
  File "/home/lucas/Programming/Python/cassandra/python-driver/cassandra/connection.py", line 242, in _handle_options_response
    % (options_response,))
ConnectionException: Did not get expected SupportedMessage response; instead, got: 6

cassandra.io.asyncorereactor: DEBUG: Closing connection (40990800) to 1.2.3.4
cassandra.io.asyncorereactor: DEBUG: Closed socket to 1.2.3.4
--------------------- >> end captured logging << ---------------------

======================================================================
FAIL: test_partial_message_read (tests.unit.io.test_asyncorereactor.AsyncoreConnectionTest)
----------------------------------------------------------------------
Traceback (most recent call last):
  File "/home/lucas/Programming/Python/cassandra/python-driver/tests/unit/io/test_asyncorereactor.py", line 272, in test_partial_message_read
    self.assertFalse(c.is_defunct)
AssertionError: True is not False
-------------------- >> begin captured logging << --------------------
cassandra.connection: DEBUG: Sending initial options message for new connection (41001040) to 1.2.3.4
cassandra.io.asyncorereactor: DEBUG: Starting asyncore event loop
cassandra.io.asyncorereactor: DEBUG: Asyncore event loop stopped unexepectedly
Traceback (most recent call last):
  File "/home/lucas/Programming/Python/cassandra/python-driver/cassandra/io/asyncorereactor.py", line 45, in _run_loop
    asyncore.loop(timeout=0.001, use_poll=True, count=None)
  File "/usr/local/lib/python2.6/asyncore.py", line 210, in loop
    poll_fun(timeout, map)
  File "/usr/local/lib/python2.6/asyncore.py", line 184, in poll2
    pollster.register(fd, flags)
TypeError: fileno() returned a non-integer
cassandra.connection: ERROR: Error decoding response from Cassandra. opcode: 0006; message contents: '\x00\x02\x00\x0bCQL_VERSION\x00\x01\x00\x053.0.1\x00\x0bCOMPRESSION\x00\x00'
Traceback (most recent call last):
  File "/home/lucas/Programming/Python/cassandra/python-driver/cassandra/connection.py", line 199, in process_msg
    response = decode_response(stream_id, flags, opcode, body, self.decompressor)
  File "/home/lucas/Programming/Python/cassandra/python-driver/cassandra/decoder.py", line 155, in decode_response
    msg_class = _message_types_by_opcode[opcode]
KeyError: 6
cassandra.connection: ERROR: Did not get expected SupportedMessage response; instead, got: 6
cassandra.io.asyncorereactor: DEBUG: Asyncore event loop ended
cassandra.io.asyncorereactor: DEBUG: Defuncting connection (41001040) to 1.2.3.4: Did not get expected SupportedMessage response; instead, got: 6
Traceback (most recent call last):
  File "/home/lucas/Programming/Python/cassandra/python-driver/cassandra/connection.py", line 103, in wrapper
    return f(self, *args, **kwargs)
  File "/home/lucas/Programming/Python/cassandra/python-driver/cassandra/connection.py", line 242, in _handle_options_response
    % (options_response,))
ConnectionException: Did not get expected SupportedMessage response; instead, got: 6

cassandra.io.asyncorereactor: DEBUG: Closing connection (41001040) to 1.2.3.4
cassandra.io.asyncorereactor: DEBUG: Closed socket to 1.2.3.4
--------------------- >> end captured logging << ---------------------

======================================================================
FAIL: test_partial_header_read (tests.unit.io.test_libevreactor.LibevConnectionTest)
----------------------------------------------------------------------
Traceback (most recent call last):
  File "/home/lucas/Programming/Python/cassandra/venv/2.6/lib/python2.6/site-packages/mock.py", line 1201, in patched
    return func(*args, **keywargs)
  File "/home/lucas/Programming/Python/cassandra/python-driver/tests/unit/io/test_libevreactor.py", line 245, in test_partial_header_read
    self.assertFalse(c.is_defunct)
AssertionError: True is not False
-------------------- >> begin captured logging << --------------------
cassandra.connection: DEBUG: Sending initial options message for new connection (42801488) to 1.2.3.4
cassandra.connection: ERROR: Error decoding response from Cassandra. opcode: 0006; message contents: '\x00\x02\x00\x0bCQL_VERSION\x00\x01\x00\x053.0.1\x00\x0bCOMPRESSION\x00\x00'
Traceback (most recent call last):
  File "/home/lucas/Programming/Python/cassandra/python-driver/cassandra/connection.py", line 199, in process_msg
    response = decode_response(stream_id, flags, opcode, body, self.decompressor)
  File "/home/lucas/Programming/Python/cassandra/python-driver/cassandra/decoder.py", line 155, in decode_response
    msg_class = _message_types_by_opcode[opcode]
KeyError: 6
cassandra.connection: ERROR: Did not get expected SupportedMessage response; instead, got: 6
cassandra.io.libevreactor: DEBUG: Defuncting connection (42801488) to 1.2.3.4: Did not get expected SupportedMessage response; instead, got: 6
Traceback (most recent call last):
  File "/home/lucas/Programming/Python/cassandra/python-driver/cassandra/connection.py", line 103, in wrapper
    return f(self, *args, **kwargs)
  File "/home/lucas/Programming/Python/cassandra/python-driver/cassandra/connection.py", line 242, in _handle_options_response
    % (options_response,))
ConnectionException: Did not get expected SupportedMessage response; instead, got: 6

cassandra.io.libevreactor: DEBUG: Closing connection (42801488) to 1.2.3.4
--------------------- >> end captured logging << ---------------------

======================================================================
FAIL: test_partial_message_read (tests.unit.io.test_libevreactor.LibevConnectionTest)
----------------------------------------------------------------------
Traceback (most recent call last):
  File "/home/lucas/Programming/Python/cassandra/venv/2.6/lib/python2.6/site-packages/mock.py", line 1201, in patched
    return func(*args, **keywargs)
  File "/home/lucas/Programming/Python/cassandra/python-driver/tests/unit/io/test_libevreactor.py", line 272, in test_partial_message_read
    self.assertFalse(c.is_defunct)
AssertionError: True is not False
-------------------- >> begin captured logging << --------------------
cassandra.connection: DEBUG: Sending initial options message for new connection (42892432) to 1.2.3.4
cassandra.connection: ERROR: Error decoding response from Cassandra. opcode: 0006; message contents: '\x00\x02\x00\x0bCQL_VERSION\x00\x01\x00\x053.0.1\x00\x0bCOMPRESSION\x00\x00'
Traceback (most recent call last):
  File "/home/lucas/Programming/Python/cassandra/python-driver/cassandra/connection.py", line 199, in process_msg
    response = decode_response(stream_id, flags, opcode, body, self.decompressor)
  File "/home/lucas/Programming/Python/cassandra/python-driver/cassandra/decoder.py", line 155, in decode_response
    msg_class = _message_types_by_opcode[opcode]
KeyError: 6
cassandra.connection: ERROR: Did not get expected SupportedMessage response; instead, got: 6
cassandra.io.libevreactor: DEBUG: Defuncting connection (42892432) to 1.2.3.4: Did not get expected SupportedMessage response; instead, got: 6
Traceback (most recent call last):
  File "/home/lucas/Programming/Python/cassandra/python-driver/cassandra/connection.py", line 103, in wrapper
    return f(self, *args, **kwargs)
  File "/home/lucas/Programming/Python/cassandra/python-driver/cassandra/connection.py", line 242, in _handle_options_response
    % (options_response,))
ConnectionException: Did not get expected SupportedMessage response; instead, got: 6

cassandra.io.libevreactor: DEBUG: Closing connection (42892432) to 1.2.3.4
--------------------- >> end captured logging << ---------------------

======================================================================
FAIL: test_unsupported_cql_version (tests.unit.test_connection.ConnectionTest)
----------------------------------------------------------------------
Traceback (most recent call last):
  File "/home/lucas/Programming/Python/cassandra/python-driver/tests/unit/test_connection.py", line 128, in test_unsupported_cql_version
    c.defunct.assert_called_once_with(ANY)
  File "/home/lucas/Programming/Python/cassandra/venv/2.6/lib/python2.6/site-packages/mock.py", line 845, in assert_called_once_with
    raise AssertionError(msg)
AssertionError: Expected to be called once. Called 2 times.
-------------------- >> begin captured logging << --------------------
cassandra.connection: ERROR: Error decoding response from Cassandra. opcode: 0006; message contents: '\x00\x02\x00\x0bCQL_VERSION\x00\x01\x00\x057.8.9\x00\x0bCOMPRESSION\x00\x00'
Traceback (most recent call last):
  File "/home/lucas/Programming/Python/cassandra/python-driver/cassandra/connection.py", line 199, in process_msg
    response = decode_response(stream_id, flags, opcode, body, self.decompressor)
  File "/home/lucas/Programming/Python/cassandra/python-driver/cassandra/decoder.py", line 155, in decode_response
    msg_class = _message_types_by_opcode[opcode]
KeyError: 6
cassandra.connection: ERROR: Did not get expected SupportedMessage response; instead, got: 6
--------------------- >> end captured logging << ---------------------

======================================================================
FAIL: test_marshalling (tests.unit.test_marshalling.TestUnmarshal)
----------------------------------------------------------------------
Traceback (most recent call last):
  File "/home/lucas/Programming/Python/cassandra/python-driver/tests/unit/test_marshalling.py", line 116, in test_marshalling
    % (valtype, marshaller, nativeval, whatwegot, serializedval))
AssertionError: True != '\x01' : Marshaller for BooleanType (<class 'cassandra.cqltypes.BooleanType'>) failed: marshal(True) got True instead of '\x01'

======================================================================
FAIL: test_unmarshalling (tests.unit.test_marshalling.TestUnmarshal)
----------------------------------------------------------------------
Traceback (most recent call last):
  File "/home/lucas/Programming/Python/cassandra/python-driver/tests/unit/test_marshalling.py", line 105, in test_unmarshalling
    % (valtype, unmarshaller, serializedval, whatwegot, nativeval))
AssertionError: None != '' : Unmarshaller for AsciiType (<class 'cassandra.cqltypes.AsciiType'>) failed: unmarshal('') got None instead of ''

======================================================================
FAIL: Smoke test cql_typename
----------------------------------------------------------------------
Traceback (most recent call last):
  File "/home/lucas/Programming/Python/cassandra/python-driver/tests/unit/test_types.py", line 105, in test_cql_typename
    self.assertEqual(cql_typename('DateType'), 'timestamp')
AssertionError: "'DateType'" != 'timestamp'

======================================================================
FAIL: Ensure lookup_casstype returns the correct classes
----------------------------------------------------------------------
Traceback (most recent call last):
  File "/home/lucas/Programming/Python/cassandra/python-driver/tests/unit/test_types.py", line 45, in test_lookup_casstype
    self.assertEqual(lookup_casstype('AsciiType'), cassandra.cqltypes.AsciiType)
AssertionError: <class 'cassandra.cqltypes.AsciiType'> != <class 'cassandra.cqltypes.AsciiType'>

======================================================================
FAIL: Ensure lookup_casstype_simple returns the correct classes
----------------------------------------------------------------------
Traceback (most recent call last):
  File "/home/lucas/Programming/Python/cassandra/python-driver/tests/unit/test_types.py", line 16, in test_lookup_casstype_simple
    self.assertEqual(lookup_casstype_simple('AsciiType'), cassandra.cqltypes.AsciiType)
AssertionError: <class 'cassandra.cqltypes.AsciiType'> != <class 'cassandra.cqltypes.AsciiType'>

----------------------------------------------------------------------
Ran 132 tests in 1.932s

FAILED (errors=2, failures=10)

######################################################################
## Python 2.7 error log
######################################################################

======================================================================
ERROR: test suite for <module 'tests.integration' from '/home/lucas/Programming/Python/cassandra/python-driver/tests/integration/__init__.py'>
----------------------------------------------------------------------
Traceback (most recent call last):
  File "/home/lucas/Programming/Python/cassandra/venv/2.7/lib/python2.7/site-packages/nose/suite.py", line 208, in run
    self.setUp()
  File "/home/lucas/Programming/Python/cassandra/venv/2.7/lib/python2.7/site-packages/nose/suite.py", line 291, in setUp
    self.setupContext(ancestor)
  File "/home/lucas/Programming/Python/cassandra/venv/2.7/lib/python2.7/site-packages/nose/suite.py", line 314, in setupContext
    try_run(context, names)
  File "/home/lucas/Programming/Python/cassandra/venv/2.7/lib/python2.7/site-packages/nose/util.py", line 469, in try_run
    return func()
  File "/home/lucas/Programming/Python/cassandra/python-driver/tests/integration/__init__.py", line 74, in setup_package
    cluster.start(wait_for_binary_proto=True)
  File "/home/lucas/Programming/Python/cassandra/venv/2.7/lib/python2.7/site-packages/ccmlib/cluster.py", line 208, in start
    p = node.start(update_pid=False)
  File "/home/lucas/Programming/Python/cassandra/venv/2.7/lib/python2.7/site-packages/ccmlib/node.py", line 304, in start
    common.check_socket_available(itf)
  File "/home/lucas/Programming/Python/cassandra/venv/2.7/lib/python2.7/site-packages/ccmlib/common.py", line 149, in check_socket_available
    raise UnavailableSocketError("Inet address %s:%s is not available: %s" % (addr, port, msg))
UnavailableSocketError: Inet address 127.0.0.1:9042 is not available: [Errno 98] Address already in use
-------------------- >> begin captured logging << --------------------
tests.integration: DEBUG: Found existing ccm test cluster, clearing
tests.integration: DEBUG: Starting ccm test cluster
tests.integration: ERROR: Failed to start ccm cluster:
Traceback (most recent call last):
  File "/home/lucas/Programming/Python/cassandra/python-driver/tests/integration/__init__.py", line 74, in setup_package
    cluster.start(wait_for_binary_proto=True)
  File "/home/lucas/Programming/Python/cassandra/venv/2.7/lib/python2.7/site-packages/ccmlib/cluster.py", line 208, in start
    p = node.start(update_pid=False)
  File "/home/lucas/Programming/Python/cassandra/venv/2.7/lib/python2.7/site-packages/ccmlib/node.py", line 304, in start
    common.check_socket_available(itf)
  File "/home/lucas/Programming/Python/cassandra/venv/2.7/lib/python2.7/site-packages/ccmlib/common.py", line 149, in check_socket_available
    raise UnavailableSocketError("Inet address %s:%s is not available: %s" % (addr, port, msg))
UnavailableSocketError: Inet address 127.0.0.1:9042 is not available: [Errno 98] Address already in use
--------------------- >> end captured logging << ---------------------

======================================================================
ERROR: Smoke test cass_parameterized_type_with
----------------------------------------------------------------------
Traceback (most recent call last):
  File "/home/lucas/Programming/Python/cassandra/python-driver/tests/unit/test_types.py", line 81, in test_cassandratype
    self.assertEqual(LongType.cass_parameterized_type_with(()), 'LongType')
  File "/home/lucas/Programming/Python/cassandra/python-driver/cassandra/cqltypes.py", line 229, in cass_parameterized_type_with
    cname = cls.cassname
AttributeError: type object 'LongType' has no attribute 'cassname'

======================================================================
FAIL: test_partial_header_read (tests.unit.io.test_asyncorereactor.AsyncoreConnectionTest)
----------------------------------------------------------------------
Traceback (most recent call last):
  File "/home/lucas/Programming/Python/cassandra/python-driver/tests/unit/io/test_asyncorereactor.py", line 245, in test_partial_header_read
    self.assertFalse(c.is_defunct)
AssertionError: True is not False
-------------------- >> begin captured logging << --------------------
cassandra.connection: DEBUG: Sending initial options message for new connection (27725456) to 1.2.3.4
cassandra.connection: ERROR: Error decoding response from Cassandra. opcode: 0006; message contents: '\x00\x02\x00\x0bCQL_VERSION\x00\x01\x00\x053.0.1\x00\x0bCOMPRESSION\x00\x00'
Traceback (most recent call last):
  File "/home/lucas/Programming/Python/cassandra/python-driver/cassandra/connection.py", line 199, in process_msg
    response = decode_response(stream_id, flags, opcode, body, self.decompressor)
  File "/home/lucas/Programming/Python/cassandra/python-driver/cassandra/decoder.py", line 155, in decode_response
    msg_class = _message_types_by_opcode[opcode]
KeyError: 6
cassandra.io.asyncorereactor: DEBUG: Starting asyncore event loop
cassandra.connection: ERROR: Did not get expected SupportedMessage response; instead, got: 6
cassandra.io.asyncorereactor: DEBUG: Asyncore event loop stopped unexepectedly
Traceback (most recent call last):
  File "/home/lucas/Programming/Python/cassandra/python-driver/cassandra/io/asyncorereactor.py", line 45, in _run_loop
    asyncore.loop(timeout=0.001, use_poll=True, count=None)
  File "/usr/lib64/python2.7/asyncore.py", line 216, in loop
    poll_fun(timeout, map)
  File "/usr/lib64/python2.7/asyncore.py", line 190, in poll2
    pollster.register(fd, flags)
TypeError: fileno() returned a non-integer
cassandra.io.asyncorereactor: DEBUG: Defuncting connection (27725456) to 1.2.3.4: Did not get expected SupportedMessage response; instead, got: 6
Traceback (most recent call last):
  File "/home/lucas/Programming/Python/cassandra/python-driver/cassandra/connection.py", line 103, in wrapper
    return f(self, *args, **kwargs)
  File "/home/lucas/Programming/Python/cassandra/python-driver/cassandra/connection.py", line 242, in _handle_options_response
    % (options_response,))
ConnectionException: Did not get expected SupportedMessage response; instead, got: 6

cassandra.io.asyncorereactor: DEBUG: Asyncore event loop ended
cassandra.io.asyncorereactor: DEBUG: Closing connection (27725456) to 1.2.3.4
cassandra.io.asyncorereactor: DEBUG: Closed socket to 1.2.3.4
--------------------- >> end captured logging << ---------------------

======================================================================
FAIL: test_partial_message_read (tests.unit.io.test_asyncorereactor.AsyncoreConnectionTest)
----------------------------------------------------------------------
Traceback (most recent call last):
  File "/home/lucas/Programming/Python/cassandra/python-driver/tests/unit/io/test_asyncorereactor.py", line 272, in test_partial_message_read
    self.assertFalse(c.is_defunct)
AssertionError: True is not False
-------------------- >> begin captured logging << --------------------
cassandra.connection: DEBUG: Sending initial options message for new connection (26972240) to 1.2.3.4
cassandra.io.asyncorereactor: DEBUG: Starting asyncore event loop
cassandra.io.asyncorereactor: DEBUG: Asyncore event loop stopped unexepectedly
Traceback (most recent call last):
  File "/home/lucas/Programming/Python/cassandra/python-driver/cassandra/io/asyncorereactor.py", line 45, in _run_loop
    asyncore.loop(timeout=0.001, use_poll=True, count=None)
  File "/usr/lib64/python2.7/asyncore.py", line 216, in loop
    poll_fun(timeout, map)
  File "/usr/lib64/python2.7/asyncore.py", line 190, in poll2
    pollster.register(fd, flags)
TypeError: fileno() returned a non-integer
cassandra.io.asyncorereactor: DEBUG: Asyncore event loop ended
cassandra.connection: ERROR: Error decoding response from Cassandra. opcode: 0006; message contents: '\x00\x02\x00\x0bCQL_VERSION\x00\x01\x00\x053.0.1\x00\x0bCOMPRESSION\x00\x00'
Traceback (most recent call last):
  File "/home/lucas/Programming/Python/cassandra/python-driver/cassandra/connection.py", line 199, in process_msg
    response = decode_response(stream_id, flags, opcode, body, self.decompressor)
  File "/home/lucas/Programming/Python/cassandra/python-driver/cassandra/decoder.py", line 155, in decode_response
    msg_class = _message_types_by_opcode[opcode]
KeyError: 6
cassandra.connection: ERROR: Did not get expected SupportedMessage response; instead, got: 6
cassandra.io.asyncorereactor: DEBUG: Defuncting connection (26972240) to 1.2.3.4: Did not get expected SupportedMessage response; instead, got: 6
Traceback (most recent call last):
  File "/home/lucas/Programming/Python/cassandra/python-driver/cassandra/connection.py", line 103, in wrapper
    return f(self, *args, **kwargs)
  File "/home/lucas/Programming/Python/cassandra/python-driver/cassandra/connection.py", line 242, in _handle_options_response
    % (options_response,))
ConnectionException: Did not get expected SupportedMessage response; instead, got: 6

cassandra.io.asyncorereactor: DEBUG: Closing connection (26972240) to 1.2.3.4
cassandra.io.asyncorereactor: DEBUG: Closed socket to 1.2.3.4
--------------------- >> end captured logging << ---------------------

======================================================================
FAIL: test_partial_header_read (tests.unit.io.test_libevreactor.LibevConnectionTest)
----------------------------------------------------------------------
Traceback (most recent call last):
  File "/home/lucas/Programming/Python/cassandra/venv/2.7/lib/python2.7/site-packages/mock.py", line 1201, in patched
    return func(*args, **keywargs)
  File "/home/lucas/Programming/Python/cassandra/python-driver/tests/unit/io/test_libevreactor.py", line 245, in test_partial_header_read
    self.assertFalse(c.is_defunct)
AssertionError: True is not False
-------------------- >> begin captured logging << --------------------
cassandra.connection: DEBUG: Sending initial options message for new connection (30748432) to 1.2.3.4
cassandra.connection: ERROR: Error decoding response from Cassandra. opcode: 0006; message contents: '\x00\x02\x00\x0bCQL_VERSION\x00\x01\x00\x053.0.1\x00\x0bCOMPRESSION\x00\x00'
Traceback (most recent call last):
  File "/home/lucas/Programming/Python/cassandra/python-driver/cassandra/connection.py", line 199, in process_msg
    response = decode_response(stream_id, flags, opcode, body, self.decompressor)
  File "/home/lucas/Programming/Python/cassandra/python-driver/cassandra/decoder.py", line 155, in decode_response
    msg_class = _message_types_by_opcode[opcode]
KeyError: 6
cassandra.connection: ERROR: Did not get expected SupportedMessage response; instead, got: 6
cassandra.io.libevreactor: DEBUG: Defuncting connection (30748432) to 1.2.3.4: Did not get expected SupportedMessage response; instead, got: 6
Traceback (most recent call last):
  File "/home/lucas/Programming/Python/cassandra/python-driver/cassandra/connection.py", line 103, in wrapper
    return f(self, *args, **kwargs)
  File "/home/lucas/Programming/Python/cassandra/python-driver/cassandra/connection.py", line 242, in _handle_options_response
    % (options_response,))
ConnectionException: Did not get expected SupportedMessage response; instead, got: 6

cassandra.io.libevreactor: DEBUG: Closing connection (30748432) to 1.2.3.4
--------------------- >> end captured logging << ---------------------

======================================================================
FAIL: test_partial_message_read (tests.unit.io.test_libevreactor.LibevConnectionTest)
----------------------------------------------------------------------
Traceback (most recent call last):
  File "/home/lucas/Programming/Python/cassandra/venv/2.7/lib/python2.7/site-packages/mock.py", line 1201, in patched
    return func(*args, **keywargs)
  File "/home/lucas/Programming/Python/cassandra/python-driver/tests/unit/io/test_libevreactor.py", line 272, in test_partial_message_read
    self.assertFalse(c.is_defunct)
AssertionError: True is not False
-------------------- >> begin captured logging << --------------------
cassandra.connection: DEBUG: Sending initial options message for new connection (30843536) to 1.2.3.4
cassandra.connection: ERROR: Error decoding response from Cassandra. opcode: 0006; message contents: '\x00\x02\x00\x0bCQL_VERSION\x00\x01\x00\x053.0.1\x00\x0bCOMPRESSION\x00\x00'
Traceback (most recent call last):
  File "/home/lucas/Programming/Python/cassandra/python-driver/cassandra/connection.py", line 199, in process_msg
    response = decode_response(stream_id, flags, opcode, body, self.decompressor)
  File "/home/lucas/Programming/Python/cassandra/python-driver/cassandra/decoder.py", line 155, in decode_response
    msg_class = _message_types_by_opcode[opcode]
KeyError: 6
cassandra.connection: ERROR: Did not get expected SupportedMessage response; instead, got: 6
cassandra.io.libevreactor: DEBUG: Defuncting connection (30843536) to 1.2.3.4: Did not get expected SupportedMessage response; instead, got: 6
Traceback (most recent call last):
  File "/home/lucas/Programming/Python/cassandra/python-driver/cassandra/connection.py", line 103, in wrapper
    return f(self, *args, **kwargs)
  File "/home/lucas/Programming/Python/cassandra/python-driver/cassandra/connection.py", line 242, in _handle_options_response
    % (options_response,))
ConnectionException: Did not get expected SupportedMessage response; instead, got: 6

cassandra.io.libevreactor: DEBUG: Closing connection (30843536) to 1.2.3.4
--------------------- >> end captured logging << ---------------------

======================================================================
FAIL: test_unsupported_cql_version (tests.unit.test_connection.ConnectionTest)
----------------------------------------------------------------------
Traceback (most recent call last):
  File "/home/lucas/Programming/Python/cassandra/python-driver/tests/unit/test_connection.py", line 128, in test_unsupported_cql_version
    c.defunct.assert_called_once_with(ANY)
  File "/home/lucas/Programming/Python/cassandra/venv/2.7/lib/python2.7/site-packages/mock.py", line 845, in assert_called_once_with
    raise AssertionError(msg)
AssertionError: Expected to be called once. Called 2 times.
-------------------- >> begin captured logging << --------------------
cassandra.connection: ERROR: Error decoding response from Cassandra. opcode: 0006; message contents: '\x00\x02\x00\x0bCQL_VERSION\x00\x01\x00\x057.8.9\x00\x0bCOMPRESSION\x00\x00'
Traceback (most recent call last):
  File "/home/lucas/Programming/Python/cassandra/python-driver/cassandra/connection.py", line 199, in process_msg
    response = decode_response(stream_id, flags, opcode, body, self.decompressor)
  File "/home/lucas/Programming/Python/cassandra/python-driver/cassandra/decoder.py", line 155, in decode_response
    msg_class = _message_types_by_opcode[opcode]
KeyError: 6
cassandra.connection: ERROR: Did not get expected SupportedMessage response; instead, got: 6
--------------------- >> end captured logging << ---------------------

======================================================================
FAIL: test_marshalling (tests.unit.test_marshalling.TestUnmarshal)
----------------------------------------------------------------------
Traceback (most recent call last):
  File "/home/lucas/Programming/Python/cassandra/python-driver/tests/unit/test_marshalling.py", line 116, in test_marshalling
    % (valtype, marshaller, nativeval, whatwegot, serializedval))
AssertionError: True != '\x01' : Marshaller for BooleanType (<class 'cassandra.cqltypes.BooleanType'>) failed: marshal(True) got True instead of '\x01'

======================================================================
FAIL: test_unmarshalling (tests.unit.test_marshalling.TestUnmarshal)
----------------------------------------------------------------------
Traceback (most recent call last):
  File "/home/lucas/Programming/Python/cassandra/python-driver/tests/unit/test_marshalling.py", line 105, in test_unmarshalling
    % (valtype, unmarshaller, serializedval, whatwegot, nativeval))
AssertionError: None != '' : Unmarshaller for AsciiType (<class 'cassandra.cqltypes.AsciiType'>) failed: unmarshal('') got None instead of ''

======================================================================
FAIL: Smoke test cql_typename
----------------------------------------------------------------------
Traceback (most recent call last):
  File "/home/lucas/Programming/Python/cassandra/python-driver/tests/unit/test_types.py", line 105, in test_cql_typename
    self.assertEqual(cql_typename('DateType'), 'timestamp')
AssertionError: "'DateType'" != 'timestamp'

======================================================================
FAIL: Ensure lookup_casstype returns the correct classes
----------------------------------------------------------------------
Traceback (most recent call last):
  File "/home/lucas/Programming/Python/cassandra/python-driver/tests/unit/test_types.py", line 45, in test_lookup_casstype
    self.assertEqual(lookup_casstype('AsciiType'), cassandra.cqltypes.AsciiType)
AssertionError: <class 'cassandra.cqltypes.AsciiType'> != <class 'cassandra.cqltypes.AsciiType'>

======================================================================
FAIL: Ensure lookup_casstype_simple returns the correct classes
----------------------------------------------------------------------
Traceback (most recent call last):
  File "/home/lucas/Programming/Python/cassandra/python-driver/tests/unit/test_types.py", line 16, in test_lookup_casstype_simple
    self.assertEqual(lookup_casstype_simple('AsciiType'), cassandra.cqltypes.AsciiType)
AssertionError: <class 'cassandra.cqltypes.AsciiType'> != <class 'cassandra.cqltypes.AsciiType'>

----------------------------------------------------------------------
Ran 132 tests in 2.210s

FAILED (errors=2, failures=10)

######################################################################
## Python 3.3 error log
######################################################################
